Workbook

Sheet DATA
A1: EmployeeID | B1: hiredate_key | C1: terminationdate_key | D1: length_of_service | E1: Emp_PrevSTATUS | F1: city_name | G1: department_name | H1: job_title | I1: store_name | J1: gender_short | K1: gender_full | L1: termreason_desc | M1: termtype_desc | N1: BUSINESS_UNIT
A2: 1338 | B2: 39288 | C2: 43849 | D2: =YEAR(C2)-YEAR(B2) -> 13 | E2: =IF(D2<=5,"Newcomer",(IF(D2>10,"Expert","proficient"))) -> Expert | F2: Vancouver | G2: Training | H2: Director, Training | I2: 35 | J2: M | K2: Male | L2: Retirement | M2: =IF(OR(L2="retirement",L2="Resignation"),"Voluntary","Involuntary") -> Voluntary | N2: HEADOFFICE
A3: 1339 | B3: 34051 | C3: 44078 | D3: =YEAR(C3)-YEAR(B3) -> 27 | E3: =IF(D3<=5,"Newcomer",(IF(D3>10,"Expert","proficient"))) -> Expert | F3: Nelson | G3: Store Management | H3: Store Manager | I3: 19 | J3: F | K3: Female | L3: Retirement | M3: =IF(OR(L3="retirement",L3="Resignation"),"Voluntary","Involuntary") -> Voluntary | N3: STORES
A4: 1340 | B4: 35551 | C4: 44088 | D4: =YEAR(C4)-YEAR(B4) -> 23 | E4: =IF(D4<=5,"Newcomer",(IF(D4>10,"Expert","proficient"))) -> Expert | F4: Kelowna | G4: Store Management | H4: Store Manager | I4: 16 | J4: M | K4: Male | L4: Retirement | M4: =IF(OR(L4="retirement",L4="Resignation"),"Voluntary","Involuntary") -> Voluntary | N4: STORES
A5: 1341 | B5: 38964 | C5: 43982 | D5: =YEAR(C5)-YEAR(B5) -> 14 | E5: =IF(D5<=5,"Newcomer",(IF(D5>10,"Expert","proficient"))) -> Expert | F5: Vancouver | G5: Labor Relations | H5: Director, Labor Relations | I5: 35 | J5: M | K5: Male | L5: Retirement | M5: =IF(OR(L5="retirement",L5="Resignation"),"Voluntary","Involuntary") -> Voluntary | N5: HEADOFFICE
A6: 1343 | B6: 37303 | C6: 44141 | D6: =YEAR(C6)-YEAR(B6) -> 18 | E6: =IF(D6<=5,"Newcomer",(IF(D6>10,"Expert","proficient"))) -> Expert | F6: Victoria | G6: Store Management | H6: Store Manager | I6: 37 | J6: F | K6: Female | L6: Retirement | M6: =IF(OR(L6="retirement",L6="Resignation"),"Voluntary","Involuntary") -> Voluntary | N6: STORES
A7: 1344 | B7: 39927 | C7: 44101 | D7: =YEAR(C7)-YEAR(B7) -> 11 | E7: =IF(D7<=5,"Newcomer",(IF(D7>10,"Expert","proficient"))) -> Expert | F7: Vancouver | G7: HR Technology | H7: Director, HR Technology | I7: 35 | J7: F | K7: Female | L7: Retirement | M7: =IF(OR(L7="retirement",L7="Resignation"),"Voluntary","Involuntary") -> Voluntary | N7: HEADOFFICE
A8: 1346 | B8: 36454 | C8: 44035 | D8: =YEAR(C8)-YEAR(B8) -> 21 | E8: =IF(D8<=5,"Newcomer",(IF(D8>10,"Expert","proficient"))) -> Expert | F8: Vancouver | G8: Employee Records | H8: Director, Employee Records | I8: 35 | J8: F | K8: Female | L8: Retirement | M8: =IF(OR(L8="retirement",L8="Resignation"),"Voluntary","Involuntary") -> Voluntary | N8: HEADOFFICE
A9: 1347 | B9: 34772 | C9: 43916 | D9: =YEAR(C9)-YEAR(B9) -> 25 | E9: =IF(D9<=5,"Newcomer",(IF(D9>10,"Expert","proficient"))) -> Expert | F9: Victoria | G9: Meats | H9: Meats Manager | I9: 37 | J9: M | K9: Male | L9: Retirement | M9: =IF(OR(L9="retirement",L9="Resignation"),"Voluntary","Involuntary") -> Voluntary | N9: STORES
A10: 1351 | B10: 38157 | C10: 43930 | D10: =YEAR(C10)-YEAR(B10) -> 16 | E10: =IF(D10<=5,"Newcomer",(IF(D10>10,"Expert","proficient"))) -> Expert | F10: Vancouver | G10: Compensation | H10: Director, Compensation | I10: 35 | J10: M | K10: Male | L10: Retirement | M10: =IF(OR(L10="retirement",L10="Resignation"),"Voluntary","Involuntary") -> Voluntary | N10: HEADOFFICE
A11: 1352 | B11: 37583 | C11: 43886 | D11: =YEAR(C11)-YEAR(B11) -> 18 | E11: =IF(D11<=5,"Newcomer",(IF(D11>10,"Expert","proficient"))) -> Expert | F11: Vancouver | G11: Legal | H11: Corporate Lawyer | I11: 35 | J11: F | K11: Female | L11: Retirement | M11: =IF(OR(L11="retirement",L11="Resignation"),"Voluntary","Involuntary") -> Voluntary | N11: HEADOFFICE
A12: 1353 | B12: 35360 | C12: 43973 | D12: =YEAR(C12)-YEAR(B12) -> 24 | E12: =IF(D12<=5,"Newcomer",(IF(D12>10,"Expert","proficient"))) -> Expert | F12: Kamloops | G12: Store Management | H12: Store Manager | I12: 15 | J12: M | K12: Male | L12: Retirement | M12: =IF(OR(L12="retirement",L12="Resignation"),"Voluntary","Involuntary") -> Voluntary | N12: STORES
A13: 1355 | B13: 41906 | C13: 44187 | D13: =YEAR(C13)-YEAR(B13) -> 6 | E13: =IF(D13<=5,"Newcomer",(IF(D13>10,"Expert","proficient"))) -> proficient | F13: Vancouver | G13: Legal | H13: Corporate Lawyer | I13: 35 | J13: M | K13: Male | L13: Retirement | M13: =IF(OR(L13="retirement",L13="Resignation"),"Voluntary","Involuntary") -> Voluntary | N13: HEADOFFICE
... A1486: 8321 | B1486: 37253 | C1486: 44119 | D1486: =YEAR(C1486)-YEAR(B1486) -> 19 | E1486: =IF(D1486<=5,"Newcomer",(IF(D1486>10,"Expert","proficient"))) -> Expert | F1486: Grand Forks | G1486: Customer Service | H1486: Cashier | I1486: 13 | J1486: F | K1486: Female | L1486: Layoff | M1486: =IF(OR(L1486="retirement",L1486="Resignation"),"Voluntary","Involuntary") -> Involuntary | N1486: STORES

Sheet SOLUTIONS
A1: Answer 1
A3: A)
B4: Total Termination | C4: 1485
A6: B)
B7: Termination growth rate: | C7: 0.07
B8: 2021 Projected Termination | C8: =ROUND(C4+(C4*C7),0) -> 1589
A10: C)
B11: Termination Growth Rate | C11: Expected Termination in 2021
B12: 0.04 | C12: =ROUND($C$4+($C$4*B12),0) -> 1544
B13: 0.045 | C13: =ROUND($C$4+($C$4*B13),0) -> 1552
B14: 0.05 | C14: =ROUND($C$4+($C$4*B14),0) -> 1559
B15: 0.055 | C15: =ROUND($C$4+($C$4*B15),0) -> 1567
B16: 0.06 | C16: =ROUND($C$4+($C$4*B16),0) -> 1574
B17: 0.065 | C17: =ROUND($C$4+($C$4*B17),0) -> 1582
B18: 0.07 | C18: =ROUND($C$4+($C$4*B18),0) -> 1589
B19: 0.075 | C19: =ROUND($C$4+($C$4*B19),0) -> 1596
B20: 0.08 | C20: =ROUND($C$4+($C$4*B20),0) -> 1604
B21: 0.085 | C21: =ROUND($C$4+($C$4*B21),0) -> 1611
B22: 0.09 | C22: =ROUND($C$4+($C$4*B22),0) -> 1619
B23: 0.095 | C23: =ROUND($C$4+($C$4*B23),0) -> 1626
B24: 0.1 | C24: =ROUND($C$4+($C$4*B24),0) -> 1634
A26: D)
B27: What would be the projected terminations if it is expected to grow by 4.5%?
B28: Termination Growth Rate | C28: Expected Termination in 2021
B29: 0.045 | C29: =VLOOKUP(B29,B12:C24,2,FALSE) -> 1552
A31: E)
B32: Total Termination
B33: Termination Type | C33: Count
B34: Retirement | C34: =COUNTIF(DATA!$L$2:L1486,SOLUTIONS!B34) -> 392
B35: Resignation | C35: =COUNTIF(DATA!$L$2:L1487,SOLUTIONS!B35) -> 385
B36: Layoff | C36: =COUNTIF(DATA!$L$2:L1488,SOLUTIONS!B36) -> 708
B38: Highest:
B39: Termination Type | C39: Count
B40: =INDEX($B$34:$B$36,MATCH(C40,$C$34:$C$36,0)) -> Layoff | C40: =MAX(C34:C36) -> 708
A42: F) | B42: a)
B43: termtype_desc column updated in DATA Table (Column M)
B44: b)
B45: Total Terminations: | C45: =+COUNTA(DATA!M2:M1486) -> 1485
B46: Total Voluntary Termination: | C46: =COUNTIF(DATA!$M$2:$M$1486,"Voluntary") -> 777
B47: Voluntary as % of total Termination: | C47: =C46/C45 -> 0.52323232
...

Sheet Questions
A1: Instructions:
A2: 1. Open Brightness_Termination_Data.xlsx
A4: Question1:
A5: You are hired by Brightness, a hypermarket chain company, as a data analyst. Your first task is to project the number of employee termination based on 2020 termination records
A6: A) What was the total number of terminations in 2020?
A7: ________________________________________
A8: B) Calculate the 2021 projected termination knowing that termination rate has grown around the world at an average of 7%
A10: Supportive formula: Projection termination of 2021 = Terminations of 2020 + (Terminations of 2020*7%)
A11: _____________________________
A12: C) After you perform the calculation, create a table to study the effect of the rate on the projection of terminations 2021 (starting from 4% until 10% with 0.5% increments __________
A13: D) What would be the projected terminations if it is expected to grow by 4.5%?
A14: _______________________________
... A32: -END OF CASE STUDY-
